2023-12-15 18:21:01.189580: I tensorflow/core/util/port.cc:113] oneDNN custom operations are on. You may see slightly different numerical results due to floating-point round-off errors from different computation orders. To turn them off, set the environment variable `TF_ENABLE_ONEDNN_OPTS=0`.
2023-12-15 18:21:01.190727: I external/local_tsl/tsl/cuda/cudart_stub.cc:31] Could not find cuda drivers on your machine, GPU will not be used.
2023-12-15 18:21:01.211075: E external/local_xla/xla/stream_executor/cuda/cuda_dnn.cc:9261] Unable to register cuDNN factory: Attempting to register factory for plugin cuDNN when one has already been registered
2023-12-15 18:21:01.211104: E external/local_xla/xla/stream_executor/cuda/cuda_fft.cc:607] Unable to register cuFFT factory: Attempting to register factory for plugin cuFFT when one has already been registered
2023-12-15 18:21:01.211676: E external/local_xla/xla/stream_executor/cuda/cuda_blas.cc:1515] Unable to register cuBLAS factory: Attempting to register factory for plugin cuBLAS when one has already been registered
2023-12-15 18:21:01.215083: I external/local_tsl/tsl/cuda/cudart_stub.cc:31] Could not find cuda drivers on your machine, GPU will not be used.
2023-12-15 18:21:01.215213: I tensorflow/core/platform/cpu_feature_guard.cc:182] This TensorFlow binary is optimized to use available CPU instructions in performance-critical operations.
To enable the following instructions: AVX2 AVX_VNNI FMA, in other operations, rebuild TensorFlow with the appropriate compiler flags.
2023-12-15 18:21:01.636886: W tensorflow/compiler/tf2tensorrt/utils/py_utils.cc:38] TF-TRT Warning: Could not find TensorRT
2023-12-15 18:21:02.485201: I external/local_xla/xla/stream_executor/cuda/cuda_executor.cc:901] successful NUMA node read from SysFS had negative value (-1), but there must be at least one NUMA node, so returning NUMA node zero. See more at https://github.com/torvalds/linux/blob/v6.0/Documentation/ABI/testing/sysfs-bus-pci#L344-L355
2023-12-15 18:21:02.485330: I external/local_xla/xla/stream_executor/cuda/cuda_executor.cc:901] successful NUMA node read from SysFS had negative value (-1), but there must be at least one NUMA node, so returning NUMA node zero. See more at https://github.com/torvalds/linux/blob/v6.0/Documentation/ABI/testing/sysfs-bus-pci#L344-L355
2023-12-15 18:21:02.495701: W tensorflow/core/common_runtime/gpu/gpu_device.cc:2256] Cannot dlopen some GPU libraries. Please make sure the missing libraries mentioned above are installed properly if you would like to use GPU. Follow the guide at https://www.tensorflow.org/install/gpu for how to download and setup the required libraries for your platform.
Skipping registering GPU devices...
Keras Uncertainty will use standalone Keras backendTraceback (most recent call last):
  File "/home/mtesnar/venvs/mystery/lib/python3.10/site-packages/keras_tuner/src/engine/base_tuner.py", line 273, in _try_run_and_update_trial
    self._run_and_update_trial(trial, *fit_args, **fit_kwargs)
  File "/home/mtesnar/venvs/mystery/lib/python3.10/site-packages/keras_tuner/src/engine/base_tuner.py", line 238, in _run_and_update_trial
    results = self.run_trial(trial, *fit_args, **fit_kwargs)
  File "/home/mtesnar/venvs/mystery/lib/python3.10/site-packages/keras_tuner/src/engine/tuner.py", line 316, in run_trial
    obj_value = self._build_and_fit_model(trial, *args, **copied_kwargs)
  File "/home/mtesnar/venvs/mystery/lib/python3.10/site-packages/keras_tuner/src/engine/tuner.py", line 235, in _build_and_fit_model
    results = self.hypermodel.fit(hp, model, *args, **kwargs)
  File "/home/mtesnar/mystery/online_learning_tuning.py", line 79, in fit
    AIOmodel = AIOModelTuning(
  File "/home/mtesnar/mystery/src/model.py", line 162, in __init__
    assert experiment_specification["MODEL_MODE"] in ["FIFO", "FIRO", "RIRO", "SPACE_HEURISTIC",
AssertionError: Mode does not exist.
Traceback (most recent call last):
  File "/home/mtesnar/venvs/mystery/lib/python3.10/site-packages/keras_tuner/src/engine/base_tuner.py", line 273, in _try_run_and_update_trial
    self._run_and_update_trial(trial, *fit_args, **fit_kwargs)
  File "/home/mtesnar/venvs/mystery/lib/python3.10/site-packages/keras_tuner/src/engine/base_tuner.py", line 238, in _run_and_update_trial
    results = self.run_trial(trial, *fit_args, **fit_kwargs)
  File "/home/mtesnar/venvs/mystery/lib/python3.10/site-packages/keras_tuner/src/engine/tuner.py", line 316, in run_trial
    obj_value = self._build_and_fit_model(trial, *args, **copied_kwargs)
  File "/home/mtesnar/venvs/mystery/lib/python3.10/site-packages/keras_tuner/src/engine/tuner.py", line 235, in _build_and_fit_model
    results = self.hypermodel.fit(hp, model, *args, **kwargs)
  File "/home/mtesnar/mystery/online_learning_tuning.py", line 79, in fit
    AIOmodel = AIOModelTuning(
  File "/home/mtesnar/mystery/src/model.py", line 162, in __init__
    assert experiment_specification["MODEL_MODE"] in ["FIFO", "FIRO", "RIRO", "SPACE_HEURISTIC",
AssertionError: Mode does not exist.
Traceback (most recent call last):
  File "/home/mtesnar/venvs/mystery/lib/python3.10/site-packages/keras_tuner/src/engine/base_tuner.py", line 273, in _try_run_and_update_trial
    self._run_and_update_trial(trial, *fit_args, **fit_kwargs)
  File "/home/mtesnar/venvs/mystery/lib/python3.10/site-packages/keras_tuner/src/engine/base_tuner.py", line 238, in _run_and_update_trial
    results = self.run_trial(trial, *fit_args, **fit_kwargs)
  File "/home/mtesnar/venvs/mystery/lib/python3.10/site-packages/keras_tuner/src/engine/tuner.py", line 316, in run_trial
    obj_value = self._build_and_fit_model(trial, *args, **copied_kwargs)
  File "/home/mtesnar/venvs/mystery/lib/python3.10/site-packages/keras_tuner/src/engine/tuner.py", line 235, in _build_and_fit_model
    results = self.hypermodel.fit(hp, model, *args, **kwargs)
  File "/home/mtesnar/mystery/online_learning_tuning.py", line 79, in fit
    AIOmodel = AIOModelTuning(
  File "/home/mtesnar/mystery/src/model.py", line 162, in __init__
    assert experiment_specification["MODEL_MODE"] in ["FIFO", "FIRO", "RIRO", "SPACE_HEURISTIC",
AssertionError: Mode does not exist.
Building that B*TCH
Building that B*TCH
Tuning that B*TCH
Building that B*TCH
Tuning that B*TCH
Building that B*TCH
Tuning that B*TCH
Traceback (most recent call last):
  File "/home/mtesnar/mystery/online_learning_tuning.py", line 114, in <module>
    tuner.search(None, None, epochs=es["MAX_EPOCHS"], validation_data=(None, None))
  File "/home/mtesnar/venvs/mystery/lib/python3.10/site-packages/keras_tuner/src/engine/base_tuner.py", line 234, in search
    self.on_trial_end(trial)
  File "/home/mtesnar/venvs/mystery/lib/python3.10/site-packages/keras_tuner/src/engine/base_tuner.py", line 338, in on_trial_end
    self.oracle.end_trial(trial)
  File "/home/mtesnar/venvs/mystery/lib/python3.10/site-packages/keras_tuner/src/distribute/oracle_client.py", line 97, in end_trial
    self.stub.EndTrial(
  File "/home/mtesnar/venvs/mystery/lib/python3.10/site-packages/grpc/_channel.py", line 1160, in __call__
    return _end_unary_response_blocking(state, call, False, None)
  File "/home/mtesnar/venvs/mystery/lib/python3.10/site-packages/grpc/_channel.py", line 1003, in _end_unary_response_blocking
    raise _InactiveRpcError(state)  # pytype: disable=not-instantiable
grpc._channel._InactiveRpcError: <_InactiveRpcError of RPC that terminated with:
	status = StatusCode.UNKNOWN
	details = "Exception calling application: Number of consecutive failures exceeded the limit of 3.
"
	debug_error_string = "UNKNOWN:Error received from peer  {grpc_message:"Exception calling application: Number of consecutive failures exceeded the limit of 3.\n", grpc_status:2, created_time:"2023-12-15T18:21:03.755264265+01:00"}"
>
